using System;

namespace TryCatch
{
    class MainApp
    {
        static void Main(string[] args)
        {
            int[] arr = { 1, 2, 3 };

            try
            {
                for (int i = 0; i <5; i++)
                {
                    Console.WriteLine(arr[i]);
                }
            }
            catch(IndexOutOfRangeException e)
            {
                Console.WriteLine($"예외가 발생했습니다 : {e.Message}");
            }

            Console.WriteLine("종료");
        }
    }
}

// try~catch문
// try
// {
//      // 실행하고자 하는 코드
// }
// catch(예외_객체_1)
// {
//      // 예외가 발생했을 떄의 처리
// }
// catch(예외_객체_2)
// {
//      // 예외가 발생했을 떄의 처리
// }
